Workbook

Sheet MOS Capex Format
B1: Overview of RSP CAPEX projects | I1: Report Month | J1: 46203
A2: S.N. | B2: Category | C2: Total no. of Projects | D2: Total cost of Projects | E2: Expenditure incurred up to FY 2025-26 | F2: CAPEX for FY 26-27 (BE) | G2: Expenditure in FY26-27 | H2: Total Expenditure (Rs cr.) | I2: Progress of Projects in column 3 No. of projects: i.On time ii.Delayed up to 01 year iii.Delayed more than 01 year (10)
A3: 1 | B3: 2 | C3: 3 | D3: 4 | E3: 5 | F3: 6 | G3: 7 | H3: 8 | I3: 9
B4: Being implemented from last FY | C4: =C5+C9 -> 28 | D4: =D5+D9 -> 5628.5499 | E4: =E5+E9 -> 1078.7716 | F4: =F5+F9 -> 1483 | G4: =G5+G9 -> 630.00588 | H4: =E4+G4 -> 1708.7775
B5: Corporate AMR | C5: =SUM(C6:C8) -> 10 | D5: =SUM(D6:D8) -> 5368.3087 | E5: =SUM(E6:E8) -> 1008.39 | F5: =SUM(F6:F8) -> 1357 | G5: =SUM(G6:G8) -> 611.24 | H5: =E5+G5 -> 1619.63
B6: Ontime | C6: 9 | D6: 5368.3087 | E6: 1008.39 | F6: 1357 | G6: 611.24 | H6: =G6+E6 -> 1619.63
B7: Delay<1 | C7: 1 | D7: 0 | E7: 0 | F7: 0 | G7: 0 | H7: =G7+E7 -> 0
B8: Delay>1 | C8: 0 | D8: 0 | E8: 0 | F8: 0 | G8: 0 | H8: =G8+E8 -> 0
B9: Plant AMR(<30 Cr.) | C9: =SUM(C10:C12) -> 18 | D9: =SUM(D10:D12) -> 260.24118 | E9: =SUM(E10:E12) -> 70.381645 | F9: =SUM(F10:F12) -> 126 | G9: =SUM(G10:G12) -> 18.765878 | H9: =E9+G9 -> 89.147523
B10: Ontime | C10: 5 | D10: 70.077388 | E10: 0.1682035 | F10: 29 | G10: 0.7443474 | H10: =G10+E10 -> 0.9125509
B11: Delay<1 | C11: 9 | D11: 116.25221 | E11: 37.735304 | F11: 63 | G11: 10.938883 | H11: =G11+E11 -> 48.674188
B12: Delay>1 | C12: 4 | D12: 73.911584 | E12: 32.478137 | F12: 34 | G12: 7.0826475 | H12: =G12+E12 -> 39.560785
B13: Implementation started during FY25-26 | C13: =C14+C18 -> 24 | D13: =D14+D18 -> 183.80397 | E13: =E14+E18 -> 0 | F13: =F14+F18 -> 33.3 | G13: =G14+G18 -> 0.0093594 | H13: =E13+G13 -> 0.0093594
B14: Corporate AMR | C14: =SUM(C15:C17) -> 0 | D14: =SUM(D15:D17) -> 0 | E14: =SUM(E15:E17) -> 0 | F14: =SUM(F15:F17) -> 0 | G14: =SUM(G15:G17) -> 0 | H14: =E14+G14 -> 0
B15: Ontime | C15: 0 | D15: 0 | E15: 0 | F15: 0 | G15: 0 | H15: =G15+E15 -> 0
B16: Delay<1 | C16: 0 | D16: 0 | E16: 0 | F16: 0 | G16: 0 | H16: =G16+E16 -> 0
B17: Delay>1 | C17: 0 | D17: 0 | E17: 0 | F17: 0 | G17: 0 | H17: =G17+E17 -> 0
B18: Plant AMR(<30 Cr.) | C18: =SUM(C19:C21) -> 24 | D18: =SUM(D19:D21) -> 183.80397 | E18: =SUM(E19:E21) -> 0 | F18: =SUM(F19:F21) -> 33.3 | G18: =SUM(G19:G21) -> 0.0093594 | H18: =E18+G18 -> 0.0093594
B19: Ontime | C19: 23 | D19: 183.41844 | E19: 0 | F19: 33 | G19: 0.0093594 | H19: =G19+E19 -> 0.0093594
B20: Delay<1 | C20: 1 | D20: 0.3855296 | E20: 0 | F20: 0.3 | G20: 0 | H20: =G20+E20 -> 0
B21: Delay>1 | C21: 0 | D21: 0 | E21: 0 | F21: 0 | G21: 0 | H21: 0
B22: Total Ongoing projects | C22: =SUM(C23:C25) -> 52 | D22: =SUM(D23:D25) -> 5812.3539 | E22: =SUM(E23:E25) -> 1078.7716 | F22: =SUM(F23:F25) -> 1516.3 | G22: =SUM(G23:G25) -> 630.01524 | H22: =E22+G22 -> 1708.7869
B23: Ontime | C23: =C19+C15+C10+C6 -> 37 | D23: =D19+D15+D10+D6 -> 5621.8045 | E23: =E19+E15+E10+E6 -> 1008.5582 | F23: =F19+F15+F10+F6 -> 1419 | G23: =G19+G15+G10+G6 -> 611.99371 | H23: =E23+G23 -> 1620.5519
B24: Delay<1 | C24: =C20+C16+C11+C7 -> 11 | D24: =D20+D16+D11+D7 -> 116.63774 | E24: =E20+E16+E11+E7 -> 37.735304 | F24: =F20+F16+F11+F7 -> 63.3 | G24: =G20+G16+G11+G7 -> 10.938883 | H24: =E24+G24 -> 48.674188
B25: Delay>1 | C25: =C21+C17+C12+C8 -> 4 | D25: =D21+D17+D12+D8 -> 73.911584 | E25: =E21+E17+E12+E8 -> 32.478137 | F25: =F21+F17+F12+F8 -> 34 | G25: =G21+G17+G12+G8 -> 7.0826475 | H25: =E25+G25 -> 39.560785
A26: 2 | B26: Milestone payments in completed projects incl. MEP | F26: =SUM(F27:F37) -> 288.50811 | G26: =SUM(G27:G37) -> 172.31476 | H26: =E26+G26 -> 172.31476
B27: MEP | C27: 1 | D27: 14240 | E27: 14183.99 | F27: 0 | G27: 0 | H27: =G27+E27 -> 14183.99
B28: Others (COB#4) | G28: 0 | H28: =G28+E28 -> 0
B29: 30 MLD STP for township | C29: 1 | D29: 96.62 | E29: 87.02 | F29: 12.2 | G29: 0.87 | H29: =G29+E29 -> 87.89
B30: TS#1 | C30: 1 | D30: 158.17 | E30: 165.65 | F30: 0 | G30: 0.21 | H30: =G30+E30 -> 165.86
B31: COB #2 | C31: 1 | D31: 433.58 | E31: 461.48 | F31: 5 | G31: 1.17 | H31: =G31+E31 -> 462.65
B32: Caster-IV | C32: 1 | D32: 1105.23 | E32: 897.96 | F32: 195 | G32: 77.7 | H32: =G32+E32 -> 975.66
B33: NHSM | C33: 1 | D33: 4033.88 | E33: 4177.77 | F33: 0 | G33: 0 | H33: =G33+E33 -> 4177.77
B34: Power enabling package for oxygen | C34: 1 | D34: 83.49 | E34: 60.28 | F34: 16 | G34: 5.29 | H34: =G34+E34 -> 65.57
B35: Plant AMR(<30 Cr.)-Completed/EDC | F35: 34.59 | G35: 80.574109 | H35: =G35+E35 -> 80.574109
B36: Plant AMR(<30 Cr.)-old schemes | C36: 9 | D36: 49.970599 | E36: 14.440753 | F36: 24.38 | G36: 5.6625383 | H36: =G36+E36 -> 20.103291
B37: Plant AMR(<30 Cr.)-new schemes | C37: 2 | D37: 1.4124068 | E37: 0 | F37: 1.3381145 | G37: 0.8381145 | H37: =G37+E37 -> 0.8381145
A38: 3a | B38: New Projects under tendering/ final approval and contract award | C38: =SUM(C39:C41) -> 15 | D38: =SUM(D39:D41) -> 440.12638 | E38: =SUM(E39:E41) -> 0.74 | F38: =SUM(F39:F41) -> 10.4 | G38: =SUM(G39:G41) -> 0 | H38: =E38+G38 -> 0.74
B39: Corporate AMR-under tendering | C39: 1 | D39: 367.15 | E39: 0.74 | F39: 0 | G39: 0 | H39: =G39+E39 -> 0.74 | I39: Coal Transportation
B40: Corporate AMR- under final approval and contract award | C40: 0 | D40: 0 | E40: 0 | F40: 0 | G40: 0 | H40: =G40+E40 -> 0
...

Sheet Format Projects-PMC
A1: Format for Projects-PMC
A2: Timeline Analysis of Ongoing Projects
C3: No of Projects | D3: Total Cost (Rs Cr) | E3: Expenditure incurred up to FY 2025-26 | F3: Financial progress in FY26-27 | H3: Total Expd till
F4: CAPEX target | G4: Expd in FY26-27 | H4: ='MOS Capex Format'!J1 -> 46203
A5: New projects (yet to be awarded) | C5: ='MOS Capex Format'!C48 -> 19 | D5: ='MOS Capex Format'!D48 -> 689.99638 | E5: ='MOS Capex Format'!E48 -> 0.74 | F5: ='MOS Capex Format'!F48 -> 10.4 | G5: ='MOS Capex Format'!G48 -> 0 | H5: ='MOS Capex Format'!H48 -> 0.74
A6: Ongoing Projects | C6: =SUM(C8:C13) -> 52 | D6: =SUM(D8:D13) -> 5812.3539 | E6: =SUM(E8:E13) -> 1078.7716 | F6: =SUM(F8:F13) -> 1516.3 | G6: =SUM(G8:G13) -> 630.01524 | H6: =SUM(H8:H13) -> 1708.7869
A7: Total Projects | C7: =C6+C5 -> 71 | D7: =D6+D5 -> 6502.3502 | E7: =E6+E5 -> 1079.5116 | F7: =F6+F5 -> 1526.7 | G7: =G6+G5 -> 630.01524 | H7: =H6+H5 -> 1709.5269
A8: Timeline of Ongoing Projects(<50 crore) | B8: On time | C8: ='MOS Capex Format'!C10+'MOS Capex Format'!C19 -> 28 | D8: ='MOS Capex Format'!D10+'MOS Capex Format'!D19 -> 253.49583 | E8: ='MOS Capex Format'!E10+'MOS Capex Format'!E19 -> 0.1682035 | F8: ='MOS Capex Format'!F10+'MOS Capex Format'!F19 -> 62 | G8: ='MOS Capex Format'!G10+'MOS Capex Format'!G19 -> 0.7537068 | H8: ='MOS Capex Format'!H10+'MOS Capex Format'!H19 -> 0.9219103
B9: Delayed upto 1 year | C9: ='MOS Capex Format'!C11+'MOS Capex Format'!C20 -> 10 | D9: ='MOS Capex Format'!D11+'MOS Capex Format'!D20 -> 116.63774 | E9: ='MOS Capex Format'!E11+'MOS Capex Format'!E20 -> 37.735304 | F9: ='MOS Capex Format'!F11+'MOS Capex Format'!F20 -> 63.3 | G9: ='MOS Capex Format'!G11+'MOS Capex Format'!G20 -> 10.938883 | H9: ='MOS Capex Format'!H11+'MOS Capex Format'!H20 -> 48.674188
B10: Delayed > 1 year | C10: ='MOS Capex Format'!C12+'MOS Capex Format'!C21 -> 4 | D10: ='MOS Capex Format'!D12+'MOS Capex Format'!D21 -> 73.911584 | E10: ='MOS Capex Format'!E12+'MOS Capex Format'!E21 -> 32.478137 | F10: ='MOS Capex Format'!F12+'MOS Capex Format'!F21 -> 34 | G10: ='MOS Capex Format'!G12+'MOS Capex Format'!G21 -> 7.0826475 | H10: ='MOS Capex Format'!H12+'MOS Capex Format'!H21 -> 39.560785
A11: Timeline of Ongoing Projects(>50 crore) | B11: On time | C11: ='MOS Capex Format'!C6+'MOS Capex Format'!C15 -> 9 | D11: ='MOS Capex Format'!D6+'MOS Capex Format'!D15 -> 5368.3087 | E11: ='MOS Capex Format'!E6+'MOS Capex Format'!E15 -> 1008.39 | F11: ='MOS Capex Format'!F6+'MOS Capex Format'!F15 -> 1357 | G11: ='MOS Capex Format'!G6+'MOS Capex Format'!G15 -> 611.24 | H11: ='MOS Capex Format'!H6+'MOS Capex Format'!H15 -> 1619.63
B12: Delayed upto 1 year | C12: ='MOS Capex Format'!C7+'MOS Capex Format'!C16 -> 1 | D12: ='MOS Capex Format'!D7+'MOS Capex Format'!D16 -> 0 | E12: ='MOS Capex Format'!E7+'MOS Capex Format'!E16 -> 0 | F12: ='MOS Capex Format'!F7+'MOS Capex Format'!F16 -> 0 | G12: ='MOS Capex Format'!G7+'MOS Capex Format'!G16 -> 0 | H12: ='MOS Capex Format'!H7+'MOS Capex Format'!H16 -> 0
B13: Delayed > 1 year | C13: ='MOS Capex Format'!C8+'MOS Capex Format'!C17 -> 0 | D13: ='MOS Capex Format'!D8+'MOS Capex Format'!D17 -> 0 | E13: ='MOS Capex Format'!E8+'MOS Capex Format'!E17 -> 0 | F13: ='MOS Capex Format'!F8+'MOS Capex Format'!F17 -> 0 | G13: ='MOS Capex Format'!G8+'MOS Capex Format'!G17 -> 0 | H13: ='MOS Capex Format'!H8+'MOS Capex Format'!H17 -> 0
A14: Other Payments related to Projects/CAPEXs
A15: Milestone payments in completed projects | F15: ='MOS Capex Format'!F26 -> 288.50811 | G15: ='MOS Capex Format'!G26 -> 172.31476 | H15: ='MOS Capex Format'!H26 -> 172.31476
A16: Spares /Capital repair | F16: ='MOS Capex Format'!F49 -> 334.8 | G16: ='MOS Capex Format'!G49 -> 2.2 | H16: ='MOS Capex Format'!H49 -> 2.2
A17: Other schemes/ JV proj
A18: Total | C18: =C7+C15+C16+C17 -> 71 | D18: =D7+D15+D16+D17 -> 6502.3502 | E18: =E7+E15+E16+E17 -> 1079.5116 | F18: =F7+F15+F16+F17 -> 2150.0081 | G18: =G7+G15+G16+G17 -> 804.53 | H18: =H7+H15+H16+H17 -> 1884.0416

Sheet Details of Ongoing Projects
B3: Details of On-going Projects As on | D3: ='Format Projects-PMC'!H4 -> 46203
B6: Category | C6: > 30 Cr | D6: < 30 Cr | H6: TOTAL
B7: Number of Total Projects | C7: =SUM(C8:C10) -> 10 | D7: =SUM(D8:D10) -> 42 | H7: =C7+D7 -> 52
B8: On Time | C8: ='Format Projects-PMC'!C11 -> 9 | D8: 28 | H8: =C8+D8 -> 37
B9: Delayed by less than year | C9: ='Format Projects-PMC'!C12 -> 1 | D9: 10 | H9: =C9+D9 -> 11
B10: Delayed by more than year | C10: ='Format Projects-PMC'!C13 -> 0 | D10: 4 | H10: =C10+D10 -> 4
B11: Projects in BOO/COM/MDO mode (Out of Total Projects) | C11: 3 | D11: 0
